Workbook

Sheet LA
B2: CONTROL DE VERSIONES
B3: Versión | C3: Hecha por: | F3: Revisada por | G3: Aprobada por | H3: Fecha | I3: Motivo:
B4: 0.1 | C4: LB | F4: DT | G4: DT | I4: Version Original
B5: LISTA DE ACTIVIDADES
B7: NOMBRE DEL PROYECTO | J7: SIGLAS DEL PROYECTO
B10: ACTIVIDAD | E10: ID | F10: EDT | G10: RECURSOS | H10: DESCRIPCIÓN | I10: PREDECESORAS | J10: SUCESORAS | K10: ADELANTO | L10: RETRASO | M10: RELACIÓN DE PRECEDENCIA

Sheet ET
B2: CONTROL DE VERSIONES
B3: Versión | C3: Hecha por: | E3: Revisada por | F3: Aprobada por | G3: Fecha | H3: Motivo:
B4: 0.1 | C4: LB | E4: DT | F4: DT | G4: 43528 | H4: Version Original
B5: ESTIMACIÓN DE TIEMPOS
B7: NOMBRE DEL PROYECTO | I7: SIGLAS DEL PROYECTO
B10: ACTIVIDAD/PAQUETE DE TRABAJO/ENTREGABLE | E10: UNIDAD DE MEDIDA | F10: RECURSOS | G10: ESTIMACIÓN ANALOGA (RENDIMIENTOS) | H10: ESTIMACIÓN POR TRES VALORES | L10: ESTIMACIÓN PARAMETRICA
H11: cO | I11: cM | J11: cP | K11: cE | L11: VALOR/UNIDAD DE MEDIDA

Sheet cronograma-costo (2)
A1: Cronograma (Planificación)
A3: DETALLE | B3: Duración dias | C3: Semanas | R3: Línea base
C4: 1 | D4: 2 | E4: 3 | F4: 4 | G4: 5 | H4: 6 | I4: 7 | J4: 8 | K4: 9 | L4: 10 | M4: 11 | N4: 12 | O4: 13 | P4: 14 | Q4: 15
A5: Desarrollo sitio web | B5: 105 | R5: =+R6+R9+R22+R35+R37 -> 795
A6: 1. Inicio | B6: 5 | C6: =+C8+C7 -> 20 | D6: =+D8+D7 -> 0 | E6: =+E8+E7 -> 0 | F6: =+F8+F7 -> 0 | G6: =+G8+G7 -> 0 | H6: =+H8+H7 -> 0 | I6: =+I8+I7 -> 0 | Q6: =+Q8+Q7 -> 0 | R6: =++C6+D6+E6+F6+G6+H6+I6+Q6 -> 20
A7: Acta | B7: 2 | C7: 5
A8: Equipo de trabajo | B8: 3 | C8: 15
A9: 2. Planificación | B9: =+B21+B20+B19+B18+B17+B16+B15+B14+B13+B12+B11+B10 -> 7 | C9: =+C11+C10 -> 0 | D9: =+D11+D10 -> 10 | E9: =+E11+E10+E12+E13+E14 -> 35 | F9: =+F11+F10+F12+F13+F14+F15+F16 -> 40 | G9: =+G11+G10+G12+G13+G14+G15+G16 -> 20 | H9: =+H11+H10+H12+H13+H14+H15+H16+H17+H18+H19 -> 90 | I9: =+I11+I10+I12+I13+I14+I15+I16+I17+I18+I19+I20+I21 -> 100 | Q9: =+Q11+Q10+Q12+Q13+Q14+Q15+Q16+Q17+Q18+Q19+Q20+Q21 -> 0 | R9: =SUM(C9:Q9) -> 295
A10: 3.1 Diseño | B10: 1 | D10: 5
A11: 3.1.1 Levantamiento información | B11: 1 | D11: 5
A12: 3.1.2 Elaboración interfaz | B12: 1 | E12: 10
A13: 3.1.3 Validaciónes | B13: 1 | E13: 20
A14: 3.2 Análisis | B14: 1 | E14: 5
A15: 3.3 Programación | B15: 1 | F15: 20
A16: 3.3.1 Código | B16: 1 | F16: 20 | G16: 20
A17: 3.3.2 Carga Inicial | B17: 0 | H17: 40
A18: 3.3.3 Integración | B18: 0 | H18: 20
A19: 3.3.4 Pruebas | B19: 0 | H19: 30
A20: 3.4 Puesta en operación | B20: 0 | I20: 60
A21: 3.5 Entregable: Página web | B21: 0 | I21: 40
A22: 3. Ejecución | B22: =+B23+B27+B28+B33+B34 -> 27 | C22: =+C24+C23 -> 0 | D22: =+D24+D23 -> 40 | E22: =+E24+E23+E25+E26+E27 -> 50 | F22: =+F24+F23+F25+F26+F27+F28+F29 -> 100 | G22: =+G24+G23+G25+G26+G27+G28+G29 -> 50 | H22: =+H24+H23+H25+H26+H27+H28+H29+H30+H31+H32 -> 60 | I22: =+I24+I23+I25+I26+I27+I28+I29+I30+I31+I32+I33+I34 -> 80 | Q22: =+Q24+Q23+Q25+Q26+Q27+Q28+Q29+Q30+Q31+Q32+Q33+Q34 -> 0 | R22: =SUM(C22:Q22) -> 380
A23: 3.1 Diseño | B23: 3 | D23: 20 | R23: =SUM(E23:Q23) -> 0
A24: 3.1.1 Levantamiento información | B24: 2 | D24: 20 | R24: =SUM(E24:Q24) -> 0
A25: 3.1.2 Elaboración interfaz | B25: 3 | E25: 30 | R25: =SUM(E25:Q25) -> 30
A26: 3.1.3 Validaciónes | B26: 3 | E26: 10 | R26: =SUM(E26:Q26) -> 10
A27: 3.2 Análisis | B27: 3 | E27: 10 | R27: =SUM(E27:Q27) -> 10
A28: 3.3 Programación | B28: =+B29+B30+B31+B32 -> 17 | F28: 50 | R28: =SUM(E28:Q28) -> 50
A29: 3.3.1 Código | B29: 11 | F29: 50 | G29: 50 | R29: =SUM(E29:Q29) -> 100
A30: 3.3.2 Carga Inicial | B30: 2 | H30: 30 | R30: =SUM(E30:Q30) -> 30
A31: 3.3.3 Integración | B31: 2 | H31: 10 | R31: =SUM(E31:Q31) -> 10
A32: 3.3.4 Pruebas | B32: 2 | H32: 20 | R32: =SUM(E32:Q32) -> 20
A33: 3.4 Puesta en operación | B33: 2 | I33: 50 | R33: =SUM(E33:Q33) -> 50
A34: 3.5 Entregable: Página web | B34: 2 | I34: 30 | R34: =SUM(E34:Q34) -> 30
A35: 4. Monitoreo y control | B35: =+B36 -> 3 | C35: =+C37+C36 -> 10 | D35: =+D37+D36 -> 10 | E35: =+E37+E36 -> 10 | F35: =+F37+F36 -> 10 | G35: =+G37+G36 -> 10 | H35: =+H36 -> 10 | I35: =+I36 -> 10 | Q35: =+Q36 -> 10 | R35: =SUM(C35:Q35) -> 80
A36: 4.1 Revisión | B36: 3 | C36: 10 | D36: 10 | E36: 10 | F36: 10 | G36: 10 | H36: 10 | I36: 10 | Q36: 10
A37: 5. Cierre | B37: =+B38+B39 -> 3 | C37: =+C39+C38 -> 0 | D37: =+D39+D38 -> 0 | E37: =+E39+E38 -> 0 | F37: =+F39+F38 -> 0 | G37: =+G39+G38 -> 0 | H37: =+H38 -> 0 | I37: =+I38 -> 0 | Q37: =+Q38+Q39 -> 20 | R37: =SUM(C37:Q37) -> 20
A38: 5.1 Reuniones | B38: 1 | Q38: 10
A39: 5.2 Informe | B39: 2 | Q39: 10
A40: Total | B40: =+B6+B9+B22+B35+B37 -> 45 | C40: =+C6+C9+C22+C35+C37 -> 30 | D40: =+D6+D9+D22+D35+D37 -> 60 | E40: =+E6+E9+E22+E35+E37 -> 95 | F40: =+F6+F9+F22+F35+F37 -> 150 | G40: =+G6+G9+G22+G35+G37 -> 80 | H40: =+H6+H9+H22+H35+H37 -> 160 | I40: =+I6+I9+I22+I35+I37 -> 190 | Q40: =+Q6+Q9+Q22+Q35+Q37 -> 30 | R40: =+C40+D40+E40+F40+G40+H40+I40+Q40 -> 795

Sheet Actividades ✓
B2: CONTROL DE VERSIONES
B3: Versión | C3: Hecha por: | F3: Revisada por | G3: Aprobada por | H3: Fecha | I3: Motivo:
B4: 0.1 | C4: LB | F4: DT | G4: DT | H4: 45892 | I4: Version Original
B5: LISTA DE ACTIVIDADES
B7: NOMBRE DEL PROYECTO | J7: SIGLAS DEL PROYECTO
B8: TechVista | J8: THV
B10: ACTIVIDAD | E10: ID | F10: EDT | G10: RECURSOS | H10: DESCRIPCIÓN | I10: PREDECESORAS | J10: SUCESORAS | K10: DURACIÓN HORAS | L10: ADELANTO | M10: RETRASO | N10: RELACIÓN DE PRECEDENCIA
B12: PLANIFICACION ESTRATEGICA | E12: 1 | F12: ACTIVIDAD | G12: GERENTE GENERAL | H12: DEFINIR MISIÓN, VISIÓN Y OBJETIVOS DEL PROYECTO. ANALIZAR LA VIABILIDAD ECONÓMICA, IMPACTO ESTRATÉGICO Y SU ALINEACIÓN CON LA MISIÓN DE LA EMPRESA. | I12: NINGUNO | J12: 1.1 - 2 | K12: =8*3 -> 24 | L12: . | M12: 3 días | N12: NINGUNO
G13: COMITÉ DIRECTIVO
G14: ANALISTA FINANCIERO
B18: DEFINICION DE METODOLOGIA DE TRABAJO | E18: 1.1 | F18: ANALISIS | G18: PMO | H18: ELEGIR Y JUSTIFICAR LA METODOLOGÍA DE GESTIÓN (SCRUM, KANBAN, PMBOK, HÍBRIDA). DEFINIR CEREMONIAS, RESPONSABLES, PERIODICIDAD DE ENTREGAS Y HERRAMIENTAS (JIRA, TRELLO, MS PROJECT). | I18: 1 | J18: =E25 -> 1.2 | K18: 8 | L18: - | M18: 2 días | N18: FIN A INICIO
G19: GERENTE DE PROYECTO
G20: LÍDERES DE ÁREA
B25: DEFINICION DE INDICADORES DE EXITO | E25: 1.2 | F25: ANALISIS | G25: GERENTE GENERAL | H25: ESTABLECER INDICADORES DE DESEMPEÑO (CUMPLIMIENTO DE HITOS, ROI, SATISFACCIÓN DE USUARIOS, TIEMPO DE ENTREGA, COSTO POR FASE). | I25: 1.1 | J25: - | K25: 6 | L25: - | M25: 2 días | N25: FIN A INICIO
G26: DIRECTOR FINANCIERO
G27: GERENTE DE DESARROLLO
B31: GESTION DE RECURSOS Y PRESUPUESTOS | E31: 2 | F31: ENTREGABLE | G31: GERENTE GENERAL | H31: ASEGURAR SOSTENIBILIDAD ECONÓMICA A LARGO PLAZO. ASIGNAR PRESUPUESTO, VALIDAR RECURSOS HUMANOS, TECNOLÓGICOS Y LOGÍSTICOS. EVALUAR PROVEEDORES EXTERNOS. | I31: =E12 -> 1 | J31: 2.1 - 3 | K31: 16 | L31: - | M31: - | N31: =B44 -> SUPERVISIÓN EJECUTIVA
G32: DIRECTOR FINANCIERO
G33: GERENTE DE DESARROLLO
B38: ASIGNACION DE PRESUPUESTO | E38: 2.1 | F38: ENTREGABLE | G38: DIRECTOR FINANCIERO | H38: DETERMINAR LOS COSTOS DE CADA FASE, APROBAR PRESUPUESTO Y ESTABLECER MECANISMOS DE CONTROL DE GASTO. | I38: 2 | J38: - | K38: 8 | L38: - | M38: - | N38: FIN A INICIO
G39: GERENTE GENERAL
B44: SUPERVISIÓN EJECUTIVA | E44: 3 | F44: ACTIVIDAD | G44: GERENTE GENERAL | H44: INFORMES PERIÓDICOS DE AVANCE Y RESULTADOS. TOMAR DECISIONES CORRECTIVAS, PRIORIZAR ACTIVIDADES Y GARANTIZAR LA ALINEACIÓN ESTRATÉGICA. | I44: 2 | J44: 3.1 - 4 | K44: - | L44: - | M44: 1 día | N44: =B31 -> GESTION DE RECURSOS Y PRESUPUESTOS
G45: GERENTE DE PROYECTO
G46: COMITÉ DE SEGUIMIENTO
B50: REVISION DE REPORTES SEMANALES | E50: 3.1 | F50: ANALISIS | G50: GERENTE DE PROYECTO | H50: REUNIONES SEMANALES PARA VALIDAR EL CUMPLIMIENTO DE HITOS Y DETECTAR RIESGOS TEMPRANOS. | I50: 3 | J50: - | K50: 3 | L50: - | M50: - | N50: FIN A INICIO
G51: LÍDERES TÉCNICOS
B56: GESTION DE RIESGOS | E56: 4 | F56: ENTREGABLE | G56: GERENTE DE RIESGOS | H56: IDENTIFICAR RIESGOS FINANCIEROS, TÉCNICOS Y LEGALES. DISEÑAR PLANES DE MITIGACIÓN Y RESPUESTA. | I56: 3 | J56: 4.1 - 5 | K56: 24 | L56: - | M56: - | N56: =B44 -> SUPERVISIÓN EJECUTIVA
G57: COMITÉ DE CUMPLIMIENTO
B62: IDENTIFICACION DE RIESGOS | E62: 4.1 | F62: ANÁLISIS | G62: GERENTE DE RIESGOS | H62: DETECTAR RIESGOS INTERNOS Y EXTERNOS EN TODAS LAS FASES (ECONÓMICOS, TECNOLÓGICOS, LEGALES) | I62: 4 | J62: =E68 -> 4.2 | K62: 4 | L62: - | N62: FIN A INICIO
G63: LÍDERES DEL ÁREA
B68: PLANES DE MITIGACION | E68: 4.2 | F68: ENTREGABLE | G68: DOCUMENTACION | H68: DEFINIR ESTRATEGIAS PARA REDUCIR LA PROBABILIDAD DE OCURRENCIA Y EL IMPACTO DE CADA RIESGO. | I68: 4.1 | J68: - | K68: 4 | L68: - | N68: FIN A INICIO
G69: COMITÉ DE RIEGOS
B74: EJECUCION | E74: 5 | F74: ACTIVIDAD | G74: GERENTE DE PROYECTO | H74: INICIAR CON EL DESARROLLO DE LOS PRIMEROS ENTREGABLES. DEFINIR CRITERIOS DE ACEPTACION DE ENTREGABLES | I74: 4 | J74: =E80 -> 5.1 | K74: 8 | L74: - | N74: FIN A INICIO
G75: GERENTE DE DESARROLLO
G76: EQUIPO DE DESARROLLO
B80: DESARROLLO DE PRIMEROS ENTREGABLES | E80: 5.1 | F80: ENTREGABLE | G80: GERENTE DE PROYECTO | H80: REALIZAR LA CONSTRUCCION, INTEGRACION Y VALIDACION DE LOS COMPONENTES DEFINIDOS PREVIAMENTE EN LA PLANIFICACION, GARANTIZANDO EL AJUSTE A LOS REQUERIMIENTOS DEL PROYECTO. | I80: - | J80: =E87 -> 5.2 | K80: =8*5 -> 40 | L80: - | N80: FIN A INICIO
G81: LÍDERES DE ÁREA
G82: EQUIPO DE DESARROLLO
G83: COMITÉ DE CALIDAD
B87: PRUEBAS DE CALIDAD E INTEGRACION | E87: 5.2 | F87: ANALISIS/ENTREGABLE | G87: EQUIPO DE CALIDAD | H87: EJECUTAR PRUEBAS DE CALIDAD PARA CONFIRMAR QUE LOS ENTREGABLES CUMPLEN LOS REQUISITOS ESTABLECIDOS | I87: =E80 -> 5.1 | J87: =E117 -> 6.3 | K87: =8*3 -> 24 | N87: FIN A INICIO
...

Sheet Cronograma ✓
A1: Cronograma (Planificación)
A3: DETALLE | B3: fecha inicio | C3: fecha fin | D3: ='Planeación y Costo ✓'!F3 -> Duración horas | E3: Agosto | AJ3: Septiembre | BN3: Octubre | CS3: Noviembre | DW3: Diciembre
E4: 1 | F4: 2 | G4: 3 | H4: 4 | I4: 5 | J4: 6 | K4: 7 | L4: 8 | M4: 9 | N4: 10 | O4: 11 | P4: 12 | Q4: 13 | R4: 14 | S4: 15 | T4: 16 | U4: 17 | V4: 18 | W4: 19 | X4: 20 | Y4: 21 | Z4: 22 | AA4: 23 | AB4: 24 | AC4: 25 | AD4: 26 | AE4: 27 | AF4: 28 | AG4: 29 | AH4: 30 | AI4: 31 | AJ4: 1 | AK4: 2 | AL4: 3 | AM4: 4 | AN4: 5 | AO4: 6 | AP4: 7 | AQ4: 8 | AR4: 9 | AS4: 10 | AT4: 11 | AU4: 12 | AV4: 13 | AW4: 14 | AX4: 15 | AY4: 16 | AZ4: 17 | BA4: 18 | BB4: 19 | BC4: 20 | BD4: 21 | BE4: 22 | BF4: 23 | BG4: 24 | BH4: 25 | BI4: 26 | BJ4: 27 | BK4: 28 | BL4: 29 | BM4: 30 | BN4: 1 | BO4: 2 | BP4: 3 | BQ4: 4 | BR4: 5 | BS4: 6 | BT4: 7 | BU4: 8 | BV4: 9 | BW4: 10 | BX4: 11 | BY4: 12 | BZ4: 13 | CA4: 14 | CB4: 15 | CC4: 16 | CD4: 17 | CE4: 18 | CF4: 19 | CG4: 20 | CH4: 21 | CI4: 22 | CJ4: 23 | CK4: 24 | CL4: 25 | CM4: 26 | CN4: 27 | CO4: 28 | CP4: 29 | CQ4: 30 | CR4: 31 | CS4: 1 | CT4: 2 | CU4: 3 | CV4: 4 | CW4: 5 | CX4: 6 | CY4: 7 | CZ4: 8 | DA4: 9 | DB4: 10 | DC4: 11 | DD4: 12 | DE4: 13 | DF4: 14 | DG4: 15 | DH4: 16 | DI4: 17 | DJ4: 18 | DK4: 19 | DL4: 20 | DM4: 21 | DN4: 22 | DO4: 23 | DP4: 24 | DQ4: 25 | DR4: 26 | DS4: 27 | DT4: 28 | DU4: 29 | DV4: 30 | DW4: 1 | DX4: 2 | DY4: 3 | DZ4: 4 | EA4: 5 | EB4: 6 | EC4: 7 | ED4: 8 | EE4: 9 | EF4: 10 | EG4: 11 | EH4: 12 | EI4: 13 | EJ4: 14 | EK4: 15 | EL4: 16 | EM4: 17 | EN4: 18 | EO4: 19 | EP4: 20 | EQ4: 21 | ER4: 22 | ES4: 23 | ET4: 24 | EU4: 25 | EV4: 26 | EW4: 27 | EX4: 28 | EY4: 29 | EZ4: 30 | FA4: 31
E5: Semana 0 | G5: Semana 1 | N5: Semana 2 | U5: Semana 3 | AB5: Semana 4 | AI5: Semana 5 | AP5: Semana 6 | AW5: Semana 7 | BD5: Semana 8 | BK5: Semana 9 | BR5: Semana 10 | BY5: Semana 11 | CF5: Semana 12 | CM5: Semana 13 | CT5: Semana 14 | DA5: Semana 15 | DH5: Semana 16 | DO5: Semana 17 | DV5: Semana 18 | EC5: Semana 19 | EJ5: Semana 20 | EQ5: Semana 21 | EX5: Semana 22
A6: Desarrollo del sistema interactivo sobre hardware y software | B6: ='Planeación y Costo ✓'!D5 -> 45870 | C6: ='Planeación y Costo ✓'!E5 -> 45991 | D6: =C6-B6 -> 121
A7: 1. INICIO
A8: ='Planeación y Costo ✓'!C8 -> 1.1. Acta | B8: ='Planeación y Costo ✓'!D8 -> 45870 | C8: ='Planeación y Costo ✓'!E8 -> 45870 | D8: ='Planeación y Costo ✓'!F8 -> 8
A9: ='Planeación y Costo ✓'!C12 -> 1.2. Equipo de Trabajo | B9: ='Planeación y Costo ✓'!D12 -> 45870 | C9: ='Planeación y Costo ✓'!E12 -> 45871 | D9: ='Planeación y Costo ✓'!F12 -> 8
A10: ='Planeación y Costo ✓'!C21 -> 1.3 Asignacion de actividades | B10: ='Planeación y Costo ✓'!D21 -> 45871 | C10: ='Planeación y Costo ✓'!E21 -> 45871 | D10: ='Planeación y Costo ✓'!F21 -> 8
A11: 2. EJECUCIÓN DEL PROYECTO
A12: 2.1. Fase 1: Análisis y Diseño
A13: ='Planeación y Costo ✓'!C25 -> 2.1.1. Análisis
A14: ='Planeación y Costo ✓'!C26 -> 2.1.1.1. Definición de los requerimientos funcionales y no funcionales del sistema. | B14: ='Planeación y Costo ✓'!D26 -> 45871 | C14: ='Planeación y Costo ✓'!E26 -> 45879 | D14: ='Planeación y Costo ✓'!F26 -> 56
A15: ='Planeación y Costo ✓'!C27 -> 2.1.1.2. Investigación de referentes. (ej: Coursera, edX, simuladores como Cisco Packet Tracer). | B15: ='Planeación y Costo ✓'!D27 -> 45879 | C15: ='Planeación y Costo ✓'!E27 -> 45886 | D15: ='Planeación y Costo ✓'!F27 -> 48
A16: ='Planeación y Costo ✓'!C28 -> 2.1.1.3 Listado de temas críticos en hardware y software (ej: arquitectura Von Neumann, ensamblaje de PCs, IoT). | B16: ='Planeación y Costo ✓'!D28 -> 45886 | C16: ='Planeación y Costo ✓'!E28 -> 45889 | D16: ='Planeación y Costo ✓'!F28 -> 24
A17: 2.1.2. Diseño
A18: ='Planeación y Costo ✓'!C30 -> 2.1.2.1. Diseño de la arquitectura de la plataforma y diagramas de flujo para interacciones clave. | B18: ='Planeación y Costo ✓'!D30 -> 45890 | C18: ='Planeación y Costo ✓'!E30 -> 45897 | D18: ='Planeación y Costo ✓'!F30 -> 52
A19: ='Planeación y Costo ✓'!C31 -> 2.1.2.2. Creación de prototipos de interfaz enfocados en usabilidad para estudiantes, con herramientas como Figma. | B19: ='Planeación y Costo ✓'!D31 -> 45897 | C19: ='Planeación y Costo ✓'!E31 -> 45905 | D19: ='Planeación y Costo ✓'!F31 -> 56
A20: ='Planeación y Costo ✓'!C32 -> 2.1.2.3. Diseño de módulos interactivos (ej: actividades como selección de palabras, cuestionarios, ejercicios para señalar partes de componentes, arrastrar y soltar, entre otras dinámicas prácticas). | B20: ='Planeación y Costo ✓'!D32 -> 45905 | C20: ='Planeación y Costo ✓'!E32 -> 45920 | D20: ='Planeación y Costo ✓'!F32 -> 72
A21: 2.2. Fase 2: Desarrollo e Implementación
A22: ='Planeación y Costo ✓'!C34 -> 2.2.1. Implementación de la aplicación
A23: ='Planeación y Costo ✓'!C35 -> 2.2.1.1. Desarrollo del frontend con tecnologías web interactivas (React.js, Three.js para modelos 3D, o Unity si se requiere mayor interactividad). | B23: ='Planeación y Costo ✓'!D35 -> 45920 | C23: ='Planeación y Costo ✓'!E35 -> 45924 | D23: ='Planeación y Costo ✓'!F35 -> 65
A24: ='Planeación y Costo ✓'!C36 -> 2.2.1.2. Construcción del backend (API REST con Node.js, gestión de usuarios, integración con bases de datos como MongoDB/PostgreSQL). | B24: ='Planeación y Costo ✓'!D36 -> 45924 | C24: ='Planeación y Costo ✓'!E36 -> 45928 | D24: ='Planeación y Costo ✓'!F36 -> 56
A25: ='Planeación y Costo ✓'!C37 -> 2.2.1.3. Integración de herramientas educativas (ej: Jupyter Notebooks para programación, Docker para laboratorios virtuales). | B25: ='Planeación y Costo ✓'!D37 -> 45929 | C25: ='Planeación y Costo ✓'!E37 -> 45930 | D25: ='Planeación y Costo ✓'!F37 -> 24
A26: ='Planeación y Costo ✓'!C38 -> 2.2.2. Pruebas y Validación
A27: ='Planeación y Costo ✓'!C39 -> 2.2.2.1. Pruebas unitarias y de integración (con frameworks como Jest, Selenium o PyTest). | B27: ='Planeación y Costo ✓'!D39 -> 45931 | C27: ='Planeación y Costo ✓'!E39 -> 45940 | D27: ='Planeación y Costo ✓'!F39 -> 80
A28: ='Planeación y Costo ✓'!C40 -> 2.2.2.2. Pruebas de usabilidad con estudiantes reales (tests A/B, feedback en tiempo real). | B28: ='Planeación y Costo ✓'!D40 -> 45941 | C28: ='Planeación y Costo ✓'!E40 -> 45949 | D28: ='Planeación y Costo ✓'!F40 -> 20
A29: ='Planeación y Costo ✓'!C41 -> 2.2.2.3. Validación de contenidos con expertos en hardware/software (correctitud técnica y pedagógica). | B29: ='Planeación y Costo ✓'!D41 -> 45950 | C29: ='Planeación y Costo ✓'!E41 -> 45955 | D29: ='Planeación y Costo ✓'!F41 -> 88
A30: ='Planeación y Costo ✓'!C42 -> 2.3. Fase 3: Despliegue y Mantenimiento
A31: ='Planeación y Costo ✓'!C43 -> 2.3.1.1. Configuración de servidores (AWS, Google Cloud, o on-premise) y despliegue de la plataforma. | B31: ='Planeación y Costo ✓'!D43 -> 45956 | C31: ='Planeación y Costo ✓'!E43 -> 45961 | D31: ='Planeación y Costo ✓'!F43 -> 10
A32: ='Planeación y Costo ✓'!C44 -> 2.3.1.2. Implementación de CDN y seguridad básica (HTTPS, firewall, backups automáticos). | B32: ='Planeación y Costo ✓'!D44 -> 45962 | C32: ='Planeación y Costo ✓'!E44 -> 45983 | D32: ='Planeación y Costo ✓'!F44 -> 42
A33: ='Planeación y Costo ✓'!C45 -> 2.3.2.3. Actualización periódica de contenidos y tecnologías (ej: nuevos modelos de hardware, frameworks actualizados). | B33: ='Planeación y Costo ✓'!D45 -> 45984 | C33: ='Planeación y Costo ✓'!E45 -> 45991 | D33: ='Planeación y Costo ✓'!F45 -> 14

Sheet Matriz RACI ✓
B1: MATRIZ RACI SIMPLE
E2: Hamilthon Ortega Gerente del Proyecto | F2: Andrés Ruiz Jefe de Recepción | G2: IngridDesarrollador Backend | H2: Britney Diseñador UX/UI | I2: Francy Bereño Técnico de TI
B3: PRIORIDAD | C3: ESTADO | D3: RESULTADO/ACTIVIDAD DEL PROYECTO | E3: Liderazgo de proyectos
D4: FASE 1
B5: Baja | C5: Completo | D5: Realizar el acta del proyecto | E5: R
B6: Media | C6: Completo | D6: Reunir al grupo | F6: A
B7: Alta | C7: Completo | D7: Asignación de actividades | G7: I
B8: Alta | C8: Completo | D8: Definición de requerimientos | E8: C | H8: I
B9: Alta | C9: Completo | D9: Investigación de requerimientos | G9: A
B10: Media | C10: Completo | D10: Consultar temas críticos en hadware y software | I10: C
D11: FASE 2
B12: Alta | C12: Completo | D12: Diseño de arquitectura de la plataforma | F12: R
B13: Alta | C13: En curso | D13: Creación de prototipos por medio de figma | G13: I
B14: Alta | C14: No se ha iniciado | D14: Diseño de modulo interactivos | F14: C | H14: A
D15: FASE 3
B16: Alta | C16: No se ha iniciado | D16: Creación de backed | G16: R
B17: Alta | C17: No se ha iniciado | D17: Desarrollo del fronted | F17: I | H17: A
B18: Alta | C18: No se ha iniciado | D18: Integración de herramientas educativas | I18: C
D19: FASE 4
B20: Alta | C20: No se ha iniciado | D20: Pruebas unitarias y de integración | E20: I | H20: R
B21: Alta | C21: No se ha iniciado | D21: Pruebas de usabilidad con estudiantes reales | F21: C | I21: C
B22: Alta | C22: No se ha iniciado | D22: Validación de contenidos con expertos | G22: A
D23: FASE 5
B24: Alta | C24: No se ha iniciado | D24: Configuración de servidores | E24: A | G24: C | I24: R
B25: Alta | C25: No se ha iniciado | D25: Implementación de seguridad básica | F25: I
C28: TECLAS DESPLEGABLES DE RACI
C29: – NO ELIMINAR –
D30: CLAVE de RACI | F30: PRIORIDAD | H30: ESTADO
C31: R | D31: Responsable | F31: Baja | H31: No se ha iniciado
C32: A | D32: A cargo | F32: Media | H32: En curso
C33: C | D33: Consultado | F33: Alta | H33: Completo
C34: I | D34: Informado | H34: Necesita revisión
H35: Aprobado
H36: Atrasado
H37: En espera

Sheet Gestión de interesados ✓
B1: Gestión de Interesados
B2: Nombre del Proyecto | H2: Gerente del Proyecto
B3: TECH VISTA | H3: Hamilthon Ortega
B4: Entregable del Proyecto | H4: fecha inicio
B5: - Identificar expectativas y necesidades de cada interesado. - Diseñar una estrategia de comunicación efectiva según su nivel de influencia. - Aumentar el compromiso de los interesados clave. - Prevenir conflictos o resistencias mediante información clara y oportuna | H5: 45870
H6: fecha fin
H7: 45997
H9: COMMUNICACION | J9: NIVEL DE COMPROMISO
B10: INTERESADO | C10: CARGO | D10: CORREO ELECTRONICO | E10: INFLUENCIA | F10: TIPO DE INFORMACION | G10: TOMADOR DE DECISIONES? | H10: Frecuencia | I10: Tipo | J10: Desconocedor | K10: En contra | L10: Neutral | M10: Colaborador | N10: Líder
B11: Hamilthon Ortega | C11: Gerente del Proyecto | D11: Hamilthone-ortegam@unilibre.edu.co | E11: Low | F11: Toma de decisiones y control del proyecto | G11: Yes | H11: Semanal | I11: Reuniones de seguimiento | M11: ✓ | N11: ✓
B12: Andres Ruiz | C12: Jefe de Recepción | D12: Andresd-ruizr@unilibre.edu.co | E12: Medium | F12: Asegurar funcionalidad y eficiencia en la recepción | G12: No | H12: Semanal | I12: Reuniones operativas | M12: ✓
B13: Francy Bereño | C13: Técnico de TI | D13: francyl-barenoo@unilibre.edu.co | E13: Medium | F13: Garantizar integración tecnológica y soporte técnico | G13: No | H13: Semanal | I13: Reuniones técnicas | L13: ✓ | M13: ✓
B14: Ingrid V Oviedo | C14: Desarrollador | D14: Ingridv-oviedon@unilibre.edu.co | E14: High | F14: Diseñar, construir y mantener la funcionalidad técnica de la aplicación | G14: Yes | H14: Semanal | I14: En operacion, desarollador | M14: ✓ | N14: ✓
B15: Britney Mora | C15: Administrativa | D15: britneym-morad@unilibre.edu.co | E15: Low | F15: Coordinar aspectos administrativos y logísticos | G15: No | H15: Mensual | I15: Correos / reuniones | J15: ✓ | M15: ✓
B16: Ingrid V Oviedo | C16: Desarrollador Backend | D16: Ingridv-oviedon@unilibre.edu.co | E16: High | F16: Implementar la lógica del sistema y gestionar la base de datos | G16: Yes | H16: Semanal | I16: Reuniones técnicas / repositorio | M16: ✓ | N16: ✓
B17: Britney Mora | C17: Diseñador UX/UI | D17: mdunn@email.com | E17: High | F17: Mejorar la experiencia de usuario y validar la usabilidad de ambas interfaces | G17: No | H17: Quincenal | I17: Revisión de prototipos / Figma | M17: ✓ | N17: ✓
B18: Francy Bareño | C18: Tester / QA | D18: francyl-barenoo@unilibre.edu.co | E18: High | F18: Detectar errores, validar funcionalidades y asegurar calidad | G18: No | H18: Semanal | I18: Informes de pruebas / reuniones | M18: ✓
B19: Britney Mora | C19: Analista de Datos | D19: britneym-morad@unilibre.edu.co | E19: Medium | F19: Medir el uso de la app y proponer mejoras basadas en métricas | G19: No | H19: Mensual | I19: Informes / dashboards | M19: ✓
B20: Andrés Ruiz | C20: Coordinador de despliegue | D20: Andresd-ruizr@unilibre.edu.co | E20: High | F20: Coordinar pruebas finales y garantizar correcto funcionamiento | G20: Yes | H20: Semanal | I20: Correos / reuniones | M20: ✓ | N20: ✓
B21: Hamilthon Ortega | C21: Gestor de Retroalimentación | D21: Hamilthone-ortegam@unilibre.edu.co | E21: Medium | F21: Recoger opiniones de estudiantes y profesores para mejorar la app | G21: No | H21: Mensual | I21: Encuestas / entrevistas | M21: ✓

Sheet Planeación y Costo ✓
C1: Planificación
B3: Código Actividad | C3: Detalle | D3: Fecha inicio | E3: Fecha fin | F3: Duración horas | G3: Recurso personal | H3: Recursos tecnicos | I3: Recursos | J3: Hora | K3: Costo | L3: Subtotal | M3: total planificado
D5: 45870 | E5: =E45 -> 45991 | F5: =SUM(F7,F23) -> 680 | G5: 5 | H5: 1 | I5: 15 | K5: =SUM(M47+M48) -> 16541342 | L5: =F47 -> 15037584 | M5: =SUM(M47+M48) -> 16541342
C6: 1.INICIO
F7: =F8+F12 -> 16 | M7: =SUM(L8:L12) -> 864974.03
C8: 1.1. Acta | D8: 45870 | E8: 45870 | F8: =SUM(F9:F11) -> 8 | G8: StakeHolders | H8: Computadora | I8: office | J8: Por hora | K8: =SUM(K9:K11) -> 175000 | L8: =SUM(L9:L11) -> 371875
B9: T001 | C9: Definir obejetivos, entregable y cronograma. | D9: 45870 | E9: =E8 -> 45870 | F9: 3 | G9: Ingeniero de Software | H9: computadora | I9: Documentación | J9: 21875 | K9: =F9*J9 -> 65625 | L9: =K9 -> 65625
B10: T002 | C10: Asignar roles y responsabilidades | D10: 45870 | E10: =E8 -> 45870 | F10: 3 | G10: Ingeniero de Software | H10: computadora | I10: Documentación | J10: 21875 | K10: =F10*J10 -> 65625 | L10: =L9+K10 -> 131250
B11: T003 | C11: Documentación de avances (actas, reportes, valores planificados) | D11: 45870 | E11: =E8 -> 45870 | F11: 2 | G11: Ingeniero de Software | H11: computadora | I11: Documentación | J11: 21875 | K11: =F11*J11 -> 43750 | L11: =L10+K11 -> 175000
C12: 1.2. Equipo de Trabajo | D12: 45870 | E12: 45871 | F12: =SUM(F13:F20) -> 8 | G12: StakeHolders | H12: Computadora | I12: office | J12: =J8 -> Por hora | K12: =SUM(K13:K20) -> 121224.03 | L12: =SUM(L13:L20) -> 121224.03
B13: T004 | C13: Coordinador de proyectos, planifica, organiza y supervisa el desarrollo. Gestiona tiempos, recursos y entregables. | D13: 45870 | E13: =E12 -> 45871 | F13: =E13-D13 -> 1 | G13: Coordinador de proyectos | H13: computadora | I13: Informes | J13: 14471 | K13: =F13*J13 -> 14471 | L13: =K13 -> 14471
B14: T005 | C14: Diseñador/a UX/UI: Crea la interfaz visual y experiencia de usuario. Diseña prototipos y estructura de navegación. | D14: 45870 | E14: =E12 -> 45871 | F14: =E14-D14 -> 1 | G14: Diseñador/ a/UX/UI | H14: computadora | I14: Informes | J14: 15132 | K14: =F14*J14 -> 15132 | L14: =K14 -> 15132
B15: T006 | C15: Desarrollador/a Frontend: Implementa la interfaz de usuario con frameworks como Angular o Ionic. | D15: 45870 | E15: =E12 -> 45871 | F15: =E15-D15 -> 1 | G15: Desarrolador/ a Fronted | H15: computadora | I15: Informes | J15: 14587.81 | K15: =F15*J15 -> 14587.81 | L15: =K15 -> 14587.81
B16: T007 | C16: Desarrollador/a Backend: Construye la lógica del servidor, base de datos y seguridad. | D16: 45870 | E16: =E12 -> 45871 | F16: =E16-D16 -> 1 | G16: Desarrolador/a Backend | H16: computadora | I16: Informes | J16: 20192.31 | K16: =F16*J16 -> 20192.31 | L16: =K16 -> 20192.31
B17: T008 | C17: Tester / QA (Quality Assurance): Realiza pruebas funcionales, de usabilidad y compatibilidad. | D17: 45870 | E17: =E12 -> 45871 | F17: =E17-D17 -> 1 | G17: Tester/ QA | H17: computadora | I17: Informes | J17: 23798.08 | K17: =F17*J17 -> 23798.08 | L17: =K17 -> 23798.08
B18: T009 | C18: Especialista en Seguridad: Garantiza protección de datos y cumplimiento de normativas. | D18: 45870 | E18: =E12 -> 45871 | F18: =E18-D18 -> 1 | G18: Especialista en seguridad | H18: computadora | I18: Informes | J18: 14086.54 | K18: =F18*J18 -> 14086.54 | L18: =K18 -> 14086.54
B19: T010 | C19: Diseñador/a de Identidad Visual: Crea el logo, paleta de colores, tipografía y estilo gráfico de la app. | D19: 45870 | E19: =E12 -> 45871 | F19: =E19-D19 -> 1 | G19: Diseñador/a de identidad visual | H19: computadora | I19: Informes | J19: 12019.23 | K19: =F19*J19 -> 12019.23 | L19: =K19 -> 12019.23
B20: T011 | C20: Responsable de Documentación: Redacta actas, reportes, manuales y seguimiento del proyecto. | D20: 45870 | E20: =E12 -> 45871 | F20: =E20-D20 -> 1 | G20: Responsable de documentacion | H20: computadora | I20: Informes | J20: 6937.06 | K20: =F20*J20 -> 6937.06 | L20: =K20 -> 6937.06
C21: 1.3 Asignacion de actividades | D21: 45871 | E21: 45871 | F21: 8 | G21: Gerente del proyecto | H21: computadora | I21: Informes | J21: 24433.44 | K21: =F21*J21 -> 195467.52 | L21: =K21 -> 195467.52
C22: 2. EJECUCIÓN DEL PROYECTO
F23: =SUM(F24+F33+F42) -> 664
C24: 2.1. Fase 1: Análisis y Diseño | F24: =(F25+F29) -> 308 | M24: =SUM(M25+M29) -> 5982284
C25: 2.1.1. Análisis | F25: =SUM(F26:F28) -> 128 | M25: =SUM(L26:L28) -> 2422392
B26: T008 | C26: 2.1.1.1. Definición de los requerimientos funcionales y no funcionales del sistema. | D26: 45871 | E26: 45879 | F26: 56 | G26: Diseñador | H26: Computadora | I26: Notion (documentación). | J26: 15132 | K26: =F26*J26 -> 847392 | L26: =K26 -> 847392
B27: T004 | C27: 2.1.1.2. Investigación de referentes. (ej: Coursera, edX, simuladores como Cisco Packet Tracer). | D27: 45879 | E27: 45886 | F27: 48 | G27: Ingeniero de Software, Diseñador. | H27: Computadora | I27: Benchmarks (Coursera, edX), ChatGPT (análisis de tendencias). | J27: 21875 | K27: =F27*J27 -> 1050000 | L27: =K27 -> 1050000
B28: T005 | C28: 2.1.1.3 Listado de temas críticos en hardware y software (ej: arquitectura Von Neumann, ensamblaje de PCs, IoT). | D28: 45886 | E28: 45889 | F28: =8*3 -> 24 | G28: Experto en Hardware/Software. | H28: Computadora | I28: Miro (mapeo de temas), Trello (priorización). | J28: 21875 | K28: =F28*J28 -> 525000 | L28: =K28 -> 525000
C29: 2.1.2. Diseño | F29: =SUM(F30:F32) -> 180 | M29: =SUM(L30:L32) -> 3559892
B30: T006 | C30: 2.1.2.1. Diseño de la arquitectura de la plataforma y diagramas de flujo para interacciones clave. | D30: 45890 | E30: 45897 | F30: =4+8*6 -> 52 | G30: Ingeniero de Software. | H30: Computadora | I30: Lucidchart (diagramas) | J30: 21875 | K30: =F30*J30 -> 1137500 | L30: =K30 -> 1137500
B31: T007 | C31: 2.1.2.2. Creación de prototipos de interfaz enfocados en usabilidad para estudiantes, con herramientas como Figma. | D31: 45897 | E31: 45905 | F31: =4*2+8*6 -> 56 | G31: Diseñador UI/UX. | H31: Computadora | I31: Figma | J31: 15132 | K31: =F31*J31 -> 847392 | L31: =K31 -> 847392
B32: T008 | C32: 2.1.2.3. Diseño de módulos interactivos (ej: actividades como selección de palabras, cuestionarios, ejercicios para señalar partes de componentes, arrastrar y soltar, entre otras dinámicas prácticas). | D32: 45905 | E32: 45920 | F32: =8*9 -> 72 | G32: Diseñador + Experto en Hardware | H32: Computadora | I32: Unity/Blender (simuladores 3D), Jupyter Notebooks. | J32: 21875 | K32: =F32*J32 -> 1575000 | L32: =K32 -> 1575000
C33: 2.2. Fase 2: Desarrollo e Implementación | F33: =F34+F38 -> 290 | M33: =SUM(M34+M38) -> 8001683
C34: 2.2.1. Implementación de la aplicación | F34: =SUM(F35:F37) -> 145 | M34: =SUM(L35:L37) -> 3171875
B35: T009 | C35: 2.2.1.1. Desarrollo del frontend con tecnologías web interactivas (React.js, Three.js para modelos 3D, o Unity si se requiere mayor interactividad). | D35: 45920 | E35: 45924 | F35: 65 | G35: Ingeniero de Software (frontend). | H35: Computadora | I35: React.js, Three.js, CSS Modules. | J35: 21875 | K35: =F35*J35 -> 1421875 | L35: =K35 -> 1421875
B36: T010 | C36: 2.2.1.2. Construcción del backend (API REST con Node.js, gestión de usuarios, integración con bases de datos como MongoDB/PostgreSQL). | D36: 45924 | E36: 45928 | F36: =7*8 -> 56 | G36: Ingeniero de Software (backend). | H36: Computadora | I36: Node.js, Django REST, PostgreSQL. | J36: 21875 | K36: =F36*J36 -> 1225000 | L36: =K36 -> 1225000
B37: T011 | C37: 2.2.1.3. Integración de herramientas educativas (ej: Jupyter Notebooks para programación, Docker para laboratorios virtuales). | D37: 45929 | E37: 45930 | F37: =3*8 -> 24 | G37: Ingeniero + Experto en contenidos. | H37: Computadora | I37: Docker (containers), VirtualBox (laboratorios). | J37: 21875 | K37: =F37*J37 -> 525000 | L37: =K37 -> 525000
C38: 2.2.2. Pruebas y Validación | F38: =SUM(F35:F37) -> 145 | M38: =SUM(L39:L41) -> 4829808
B39: T012 | C39: 2.2.2.1. Pruebas unitarias y de integración (con frameworks como Jest, Selenium o PyTest). | D39: 45931 | E39: 45940 | F39: 80 | G39: Tester, Ingeniero. | H39: Computadora | I39: Jest (unitarias), Selenium (E2E). | J39: 23798.08 | K39: =F39*J39 -> 1903846.4 | L39: =K39 -> 1903846.4
B40: T013 | C40: 2.2.2.2. Pruebas de usabilidad con estudiantes reales (tests A/B, feedback en tiempo real). | D40: 45941 | E40: 45949 | F40: 20 | G40: Tester, Estudiantes beta. | H40: Computadora | I40: Google Analytics. | J40: 23798.08 | K40: =F40*J40 -> 475961.6 | L40: =K40 -> 475961.6
B41: T014 | C41: 2.2.2.3. Validación de contenidos con expertos en hardware/software (correctitud técnica y pedagógica). | D41: 45950 | E41: 45955 | F41: =44*2 -> 88 | G41: Experto en Hardware/Software. | H41: Computadora | I41: Checklists técnicos | J41: 21875 | K41: =F41*J41 -> 1925000 | L41: =L28+K41 -> 2450000
C42: 2.3. Fase 3: Despliegue y Mantenimiento | F42: =SUM(F43:F45) -> 66 | M42: =SUM(L43:L45) -> 1053617
...

Sheet Costo Real ✓
B3: Costo Real
B5: Detalle | C5: Requisitos | D5: Fecha inicio | E5: Fecha fin | F5: Costo por hora | G5: Semanas | H5: Costo | I5: Total planificado
B7: Equipo de trabajo
I8: =SUM(I9:I15) -> 171000000
B9: Gerente de proyectos. | C9: Dirección estratégica, planificación, control | D9: 45870 | E9: 45971 | F9: 160000 | G9: 24 | H9: 6000000 | I9: =H9*(G9/4) -> 36000000
B10: Desarrollador Frontend | C10: Diseño de interfaz para estudiantes y profesores | D10: 45870 | E10: 45971 | F10: 100000 | G10: 24 | H10: 5000000 | I10: =H10*(G10/4) -> 30000000
B11: Desarrollador Backend | C11: Lógica del sistema, base de datos, seguridad | D11: 45870 | E11: 45971 | F11: 120000 | G11: 24 | H11: 5000000 | I11: =H11*(G11/4) -> 30000000
B12: Diseñador UX/UI | C12: Prototipado, experiencia de usuario | D12: 45870 | E12: 45971 | F12: 120000 | G12: 24 | H12: 4000000 | I12: =H12*(G12/4) -> 24000000
B13: Tester / QA | C13: Pruebas funcionales, control de calidad | D13: 45870 | E13: 45971 | F13: 80000 | G13: 24 | H13: 3500000 | I13: =H13*(G13/4) -> 21000000
B14: Coordinador de despliegue | C14: Planificación de la entrega, coordinación de pruebas piloto, capacitación a usuarios | D14: 45870 | E14: 45971 | F14: 100000 | G14: 6 | H14: 4000000 | I14: =H14*(G14/4) -> 6000000
B15: Coordinador Académico | C15: Definición de contenidos y criterios pedagógicos | D15: 45870 | E15: 45971 | F15: 100000 | G15: 24 | H15: 4000000 | I15: =H15*(G15/4) -> 24000000
B16: Profesor Líder | C16: Validación funcional desde el rol docente | D16: 45870 | E16: 45971 | F16: 120000 | G16: 24 | H16: 3000000 | I16: =H16*(G16/4) -> 18000000
B17: Infraestructura Técnica
I18: =SUM(I19,I20,I21,I22,I23,I24) -> 21150000
B19: Servidor en la nube | C19: Hosting, base de datos, escalabilidad | D19: 45870 | E19: 45971 | F19: - | G19: 18 | H19: 800000 | I19: =H19*(G19/4) -> 3600000
B20: Licencia Android Studio | C20: IDE para desarrollo móvil | D20: 45870 | E20: 45971 | F20: 0 | G20: 18 | H20: 1200000 | I20: =H20*(G20/4) -> 5400000
B21: Licencia Ionic / Angular | C21: Frameworks y herramientas premium | D21: 45870 | E21: 45971 | F21: 396000 | G21: 18 | H21: 2000000 | I21: =H21*(G21/4) -> 9000000
B22: Herramientas de diseño (Figma, Adobe) | C22: Prototipado y diseño colaborativo | D22: 45870 | E22: 45971 | F22: 48000 | G22: 18 | H22: 300000 | I22: =H22*(G22/4) -> 1350000
B23: Sistema de tickets / soporte | C23: Atención técnica a usuarios | D23: 45870 | E23: 45971 | F23: 211960 | G23: 18 | H23: 250000 | I23: =H23*(G23/4) -> 1125000
B24: Repositorio privado (GitHub, GitLab) | C24: Control de versiones y colaboración técnica | D24: 45870 | E24: 45971 | F24: 76000 | G24: 18 | H24: 150000 | I24: =H24*(G24/4) -> 675000
B25: Administrativo
I26: =SUM(I27,I28,I29) -> 2925000
B27: Encuestas y entrevistas | C27: Retroalimentación de estudiantes y docentes | D27: 45870 | E27: 45971 | G27: 18 | H27: 300000 | I27: =H27*(G27/4) -> 1350000
B28: Reuniones virtuales (Zoom, Teams) | C28: Coordinación del equipo | D28: 45870 | E28: 45971 | G28: 18 | H28: 200000 | I28: =H28*(G28/4) -> 900000
B29: Boletines y correos informativos | C29: Difusión de avances y novedades | D29: 45870 | E29: 45971 | G29: 18 | H29: 150000 | I29: =H29*(G29/4) -> 675000
B30: Validación y pruebas
I31: =SUM(I32:I34) -> 9000000
B32: Pruebas piloto con estudiantes | C32: Evaluación funcional desde el usuario fina | D32: 45870 | E32: 45971 | G32: 18 | H32: 500000 | I32: =H32*(G32/4) -> 2250000
B33: Pruebas de usabilidad docente | C33: Validación de interfaz y funcionalidades | D33: 45870 | E33: 45971 | G33: 18 | H33: 500000 | I33: =H33*(G33/4) -> 2250000
B34: Simulación de carga y rendimiento | C34: Evaluación técnica de escalabilidad | D34: 45870 | E34: 45971 | G34: 18 | H34: 1000000 | I34: =H34*(G34/4) -> 4500000
B35: Total | I35: =SUM(I8+I18+I26+I31) -> 204075000
B36: Imprevistos (10%) | I36: =I35*0.1 -> 20407500
B37: Perdidas | I37: =SUM(I41) -> 44000000
B38: Total + Imprevistos (10%)+ Descuentos | I38: =SUM(I35,I37) -> 248075000
B40: Perdidas
I41: 44000000
B42: Equipo de desarrollo | C42: Retrasos en la codificación de módulos clave (gestión académica y usuarios). Retrabajo por inconsistencias en los requerimientos funcionales y fallas al integrar componentes del backend con la base de datos. | D42: 45870 | E42: 45997 | G42: 4 | H42: 22000000 | I42: 22000000
B43: Infraestructura técnica | C43: Costos adicionales por mantener servidores activos sin uso productivo, consumo extra de nube, licencias temporales extendidas y necesidad de soporte técnico adicional. | D43: 45870 | E43: 45997 | G43: 4 | H43: 6000000 | I43: 6000000 | XER43: -
B44: Validación y pruebas (QA) | C44: Atrasos en pruebas de rendimiento y correcciones repetidas debido a errores no detectados en los sprints previos. Se amplió el tiempo de testeo y se reprogramaron entregas. | D44: 45870 | E44: 45997 | G44: 4 | H44: 5500000 | I44: 5500000
B45: Gestión y coordinación administrativa | C45: Reuniones adicionales de seguimiento, replanificación de cronogramas, y ajustes en reportes de avance. Impacto en la productividad del equipo por sobrecarga administrativa. | D45: 45870 | E45: 45997 | G45: 4 | H45: 3500000 | I45: 3500000
...

Sheet Planificado vs costo real ✓
B2: Codigo T | C2: DETALLE | D2: Duración dias | E2: Subtotal Planificado | F2: Total Planificado | G2: Total Real | I2: Semana | J2: 1 | K2: 2 | L2: 3 | M2: 4 | N2: 5 | O2: 6 | P2: 7 | Q2: 8
C3: 1.INICIO | F3: =F4 -> 20000000 | G3: =G4 -> #REF! | I3: Valor Planificado ($) | J3: =Tabla1[[#This Row],[Total Planificado]] -> 20000000 | K3: 20000000 | L3: 20000000 | M3: 20000000 | N3: 20000000 | O3: 20000000 | P3: 20000000 | Q3: 20000000
D4: 5 | E4: =(Tabla1[[#This Row],[Total Planificado]]+Tabla1[[#This Row],[Total Real]])/2 -> #REF! | F4: =SUM(F5:F6) -> 20000000 | G4: =SUM(G5:G6) -> #REF! | I4: Costo Real ($) | J4: =G3 -> #REF! | K4: 20000000 | L4: 20000000 | M4: 20000000 | N4: 20000000 | O4: 20000000 | P4: 20000000 | Q4: 20000000
B5: T001 | C5: 1.1. Acta | D5: 2 | E5: =(Tabla1[[#This Row],[Total Planificado]]+Tabla1[[#This Row],[Total Real]])/2 -> #REF! | F5: ='[1]Planeación y Costo ✓'!M8 -> 10000000 | G5: =#REF! -> #REF!
B6: T002 | C6: 1.2. Equipo de Trabajo | D6: 3 | E6: =(Tabla1[[#This Row],[Total Planificado]]+Tabla1[[#This Row],[Total Real]])/2 -> #REF! | F6: ='[1]Planeación y Costo ✓'!M12 -> 10000000 | G6: =#REF! -> #REF!
C7: 2. EJECUCIÓN DEL PROYECTO | E7: =(Tabla1[[#This Row],[Total Planificado]]+Tabla1[[#This Row],[Total Real]])/2 -> #REF! | F7: =SUM(F8,F17) -> 213000000 | G7: =SUM(G8,G17) -> #REF!
C8: 2.1. Fase 1: Análisis y Diseño | D8: 70 | E8: =(Tabla1[[#This Row],[Total Planificado]]+Tabla1[[#This Row],[Total Real]])/2 -> #REF! | F8: =SUM(F9,F13) -> 60000000 | G8: =SUM(G9,G13) -> #REF!
C9: 2.1.1. Planeacion | D9: 28 | E9: =(Tabla1[[#This Row],[Total Planificado]]+Tabla1[[#This Row],[Total Real]])/2 -> #REF! | F9: =SUM(F10:F12) -> 28000000 | G9: =SUM(G10:G12) -> #REF!
B10: T003 | C10: 2.1.1.1 Definición de los requerimientos funcionales y no funcionales del sistema. | E10: =(Tabla1[[#This Row],[Total Planificado]]+Tabla1[[#This Row],[Total Real]])/2 -> #REF! | F10: ='[1]Planeación y Costo ✓'!M26 -> 10000000 | G10: =#REF! -> #REF!
B11: T004 | C11: 2.1.1.2 Investigación de referentes. | E11: =(Tabla1[[#This Row],[Total Planificado]]+Tabla1[[#This Row],[Total Real]])/2 -> #REF! | F11: ='[1]Planeación y Costo ✓'!M27 -> 8000000 | G11: =#REF! -> #REF!
B12: T005 | C12: 2.1.1.3 Listado de temas críticos en hardware y software | E12: =(Tabla1[[#This Row],[Total Planificado]]+Tabla1[[#This Row],[Total Real]])/2 -> #REF! | F12: ='[1]Planeación y Costo ✓'!M28 -> 10000000 | G12: =#REF! -> #REF!
C13: 2.1.2. Diseño | D13: 42 | E13: =(Tabla1[[#This Row],[Total Planificado]]+Tabla1[[#This Row],[Total Real]])/2 -> 32000000 | F13: =SUM(F14:F16) -> 32000000 | G13: =SUM(G14:G16) -> 32000000
B14: T006 | C14: 2.1.2.1 Diseño de la arquitectura de la plataforma y diagramas de flujo para interacciones clave. | E14: =(Tabla1[[#This Row],[Total Planificado]]+Tabla1[[#This Row],[Total Real]])/2 -> 15000000 | F14: ='[1]Planeación y Costo ✓'!M30 -> 15000000 | G14: ='[1]Planeación y Costo ✓'!M30 -> 15000000
B15: T007 | C15: 2.1.2.2 Creación de prototipos de interfaz enfocados en usabilidad para estudiantes, con herramientas como Figma. | E15: =(Tabla1[[#This Row],[Total Planificado]]+Tabla1[[#This Row],[Total Real]])/2 -> 15000000 | F15: ='[1]Planeación y Costo ✓'!M31 -> 15000000 | G15: ='[1]Planeación y Costo ✓'!M31 -> 15000000
B16: T008 | C16: 2.1.2.3 Diseño de módulos interactivos | E16: =(Tabla1[[#This Row],[Total Planificado]]+Tabla1[[#This Row],[Total Real]])/2 -> 2000000 | F16: ='[1]Planeación y Costo ✓'!M32 -> 2000000 | G16: ='[1]Planeación y Costo ✓'!M32 -> 2000000
C17: 2.2. Fase 2: Desarrollo e Implementación | D17: 92 | E17: =(Tabla1[[#This Row],[Total Planificado]]+Tabla1[[#This Row],[Total Real]])/2 -> #REF! | F17: =SUM(F18,F22,F26) -> 153000000 | G17: =SUM(G18,G22,G26) -> #REF!
C18: 2.2.1. Implementación de la aplicación | D18: 63 | E18: =(Tabla1[[#This Row],[Total Planificado]]+Tabla1[[#This Row],[Total Real]])/2 -> #REF! | F18: =SUM(F19:F21) -> 59000000 | G18: =SUM(G19:G21) -> #REF!
B19: T009 | C19: 2.2.1.1 Desarrollo del frontend con tecnologías web interactivas | E19: =(Tabla1[[#This Row],[Total Planificado]]+Tabla1[[#This Row],[Total Real]])/2 -> #REF! | F19: ='[1]Planeación y Costo ✓'!M35 -> 15000000 | G19: =#REF! -> #REF!
B20: T010 | C20: 2.2.1.2 Construcción del backend | E20: =(Tabla1[[#This Row],[Total Planificado]]+Tabla1[[#This Row],[Total Real]])/2 -> #REF! | F20: ='[1]Planeación y Costo ✓'!M36 -> 20000000 | G20: =#REF! -> #REF!
B21: T011 | C21: 2.2.1.3 Integración de herramientas educativas | E21: =(Tabla1[[#This Row],[Total Planificado]]+Tabla1[[#This Row],[Total Real]])/2 -> #REF! | F21: ='[1]Planeación y Costo ✓'!M37 -> 24000000 | G21: =#REF! -> #REF!
C22: 2.2.2. Pruebas y Validación | D22: 29 | E22: =(Tabla1[[#This Row],[Total Planificado]]+Tabla1[[#This Row],[Total Real]])/2 -> #REF! | F22: =SUM(F23:F25) -> 47000000 | G22: =SUM(G23:G25) -> #REF!
B23: T012 | C23: 2.2.1.1 Pruebas unitarias y de integración | E23: =(Tabla1[[#This Row],[Total Planificado]]+Tabla1[[#This Row],[Total Real]])/2 -> #REF! | F23: ='[1]Planeación y Costo ✓'!M39 -> 15000000 | G23: =#REF! -> #REF!
B24: T013 | C24: 2.2.1.2 Pruebas de usabilidad con estudiantes reales | E24: =(Tabla1[[#This Row],[Total Planificado]]+Tabla1[[#This Row],[Total Real]])/2 -> #REF! | F24: ='[1]Planeación y Costo ✓'!M40 -> 12000000 | G24: =#REF! -> #REF!
B25: T014 | C25: 2.2.1.3 Validación de contenidos con expertos en hardware/software (correctitud técnica y pedagógica). | E25: =(Tabla1[[#This Row],[Total Planificado]]+Tabla1[[#This Row],[Total Real]])/2 -> #REF! | F25: ='[1]Planeación y Costo ✓'!M41 -> 20000000 | G25: =#REF! -> #REF!
C26: 2.3. Fase 3: Despliegue y Mantenimiento | D26: 34 | E26: =(Tabla1[[#This Row],[Total Planificado]]+Tabla1[[#This Row],[Total Real]])/2 -> #REF! | F26: =SUM(F27:F29) -> 47000000 | G26: =SUM(G27:G29) -> #REF!
B27: T015 | C27: 2.3.1.1 Configuración de servidores y despliegue de la plataforma. | E27: =(Tabla1[[#This Row],[Total Planificado]]+Tabla1[[#This Row],[Total Real]])/2 -> #REF! | F27: ='[1]Planeación y Costo ✓'!M43 -> 15000000 | G27: =#REF! -> #REF!
B28: T016 | C28: 2.3.1.2 Implementación de CDN y seguridad básica | E28: =(Tabla1[[#This Row],[Total Planificado]]+Tabla1[[#This Row],[Total Real]])/2 -> #REF! | F28: ='[1]Planeación y Costo ✓'!M44 -> 20000000 | G28: =#REF! -> #REF! | L28: ¿
B29: T017 | C29: 2.3.1.3 Actualización periódica de contenidos y tecnologías | E29: =(Tabla1[[#This Row],[Total Planificado]]+Tabla1[[#This Row],[Total Real]])/2 -> #REF! | F29: ='[1]Planeación y Costo ✓'!M45 -> 12000000 | G29: =#REF! -> #REF!
C30: 3. MANTENIMIENTO Y CONTROL | F30: =SUM(F32:F33) -> 35000000 | G30: =SUM(G32:G33) -> 35000000
D31: 30 | F31: =F34 -> - | G31: =G34 -> #REF!
B32: T018 | C32: Configuración de servidores y despliegue | E32: =(Tabla1[[#This Row],[Total Planificado]]+Tabla1[[#This Row],[Total Real]])/2 -> 15000000 | F32: 15000000 | G32: 15000000
B33: T019 | C33: Implementación de CDN y seguridad básica | E33: =(Tabla1[[#This Row],[Total Planificado]]+Tabla1[[#This Row],[Total Real]])/2 -> 20000000 | F33: 20000000 | G33: 20000000
B34: T020 | C34: Actualización periódica de contenidos y tecnología | F34: ='[1]Planeación y Costo ✓'!M49 -> - | G34: =#REF! -> #REF!
C36: Total | D36: 207 | E36: =(Tabla1[[#This Row],[Total Planificado]]+Tabla1[[#This Row],[Total Real]])/2 -> #REF! | F36: =SUM(F3,F7,F30) -> 268000000 | G36: =SUM(G3,G7,G30) -> #REF!
C37: Imprevistos (10%) | F37: =F36*0.1 -> 26800000 | G37: =G36*0.1 -> #REF!
C38: Total Proyecto | F38: =F36+F37 -> 294800000 | G38: =G36+G37 -> #REF!
B43: Actividad | C43: Presupuestado | D43: Costo real
B44: T001 | C44: 20000000 | D44: 20000000
B45: T002 | C45: 10000000 | D45: 10000000
B46: T003 | C46: 10000000 | D46: 10000000
...

Sheet Evaluación de riesgo ✓
A1: Evaluación de Riesgos del Proyecto
A2: ID del Proyecto | B2: TECH VISTA | H2: Gerente del Proyecto
A3: 1245 | H3: Hamilthon Ortega
D5: PRE-MITIGACION | H5: POST-MITIGACION
A6: REF / ID | B6: ACTIVIDAD | C6: RIESGO | D6: SEVERIDAD DE RIESGO | E6: PROBABILIDAD DE RIESGO | F6: NIVEL DE RIESGO | G6: MITIGACIONS /ADVERTENCIAS / ACCIONES CORRECTIVAS | H6: SEVERIDAD DE RIESGO | I6: PROBABILIDAD DE RIESGO | J6: NIVEL DE RIESGO | K6: ACEPTABLE PARA CONTINUAR
A7: 1 | B7: Desarrollo de la aplicación | C7: Falla técnica (bugs críticos) | D7: TOLERABLE | E7: POSIBLE | F7: HIGH | G7: Pruebas unitarias, integrales y revisiones de código | H7: TOLERABLE | I7: POSIBLE | J7: MEDIUM | K7: YES
A8: 2 | B8: Planificación del proyecto | C8: Retrasos en el cronograma | D8: TOLERABLE | E8: PROBABLE | F8: HIGH | G8: Mejorar estimaciones, asignar recursos extra, seguimiento semanal | H8: TOLERABLE | I8: PROBABLE | J8: MEDIUM | K8: YES
A9: 3 | B9: Capacitación del equipo | C9: Falta de conocimientos técnicos | D9: INDESEABLE | E9: IMPROBABLE | F9: MEDIUM | G9: Capacitaciones, mentoring y consulta con expertos externos | H9: ACEPTABLE | I9: POSIBLE | J9: LOW | K9: YES
A10: 4 | B10: Implementación | C10: Problemas de compatibilidad | D10: ACEPTABLE | E10: POSIBLE | F10: EXTREME | G10: Pruebas en diferentes dispositivos y navegadores | H10: TOLERABLE | I10: PROBABLE | J10: MEDIUM | K10: YES
A11: 5 | B11: Seguridad de la aplicación | C11: Vulnerabilidades de seguridad | D11: INDESEABLE | E11: POSIBLE | F11: HIGH | G11: ` | H11: TOLERABLE | I11: POSIBLE | J11: MEDIUM | K11: YES
A12: 6 | B12: Gestión de la información | C12: Pérdida de datos | D12: INDESEABLE | E12: POSIBLE | F12: HIGH | G12: Respaldos automáticos, plan de recuperación ante fallos | H12: TOLERABLE | I12: POSIBLE | J12: MEDIUM | K12: YES
A13: 7 | B13: Adopción del sistema | C13: Baja aceptación por usuarios | D13: ACEPTABLE | E13: POSIBLE | F13: MEDIUM | G13: Recolectar feedback, mejorar UX y capacitar usuarios | H13: ACEPTABLE | I13: POSIBLE | J13: LOW | K13: YES
A14: 8 | B14: Recursos del proyecto | C14: Falta de presupuesto o recursos | D14: TOLERABLE | E14: POSIBLE | F14: MEDIUM | G14: Priorización de funcionalidades críticas y optimización de recursos | H14: ACEPTABLE | I14: POSIBLE | J14: LOW | K14: YES
A15: 9 | B15: Gestión del alcance | C15: Cambios en requisitos | D15: ACEPTABLE | E15: PROBABLE | F15: HIGH | G15: Implementar control de cambios formal y documentar ajustes | H15: TOLERABLE | I15: PROBABLE | J15: MEDIUM | K15: NO
A16: 10 | B16: Implementación técnica | C16: Problemas de compatibilidad (móviles, navegadores) | D16: INDESEABLE | E16: POSIBLE | F16: HIGH | G16: Pruebas en distintos sistemas operativos, navegadores y dispositivos | H16: TOLERABLE | I16: POSIBLE | J16: MEDIUM | K16: YES
A17: 11 | B17: Gestión de datos y privacidad | C17: Fuga o exposición de datos sensibles de los estudiantes | D17: INDESEABLE | E17: POSIBLE | F17: HIGH | G17: Aplicar cifrado, controles de acceso, auditorías de seguridad y copias de respaldo. | H17: TOLERABLE | I17: IMPROBABLE | J17: LOW | K17: YES
A18: 12 | B18: Uso del sistema por parte de estudiantes y docentes | C18: Resistencia al cambio y baja adopción | D18: INDESEABLE | E18: PROBABLE | F18: HIGH | G18: Capacitación, manuales de usuario, soporte técnico inicial, retroalimentación continua. | H18: TOLERABLE | I18: POSIBLE | J18: MEDIUM | K18: YES
... A23: 17 | B23: Comunicación del equipo | C23: Falta de comunicación entre miembros | D23: TOLERABLE | E23: PROBABLE | F23: HIGH | G23: Reuniones semanales, herramientas colaborativas (Trello, Slack, etc.) | H23: TOLERABLE | I23: IMPROBABLE | J23: LOW | K23: YES

Sheet Matriz Impacto ✓
A2: MATRIZ DE IMPACTO
A3: PROBABILIDAD | B3: PORCENTAJE ASIGNADO (1 al 100%) | C3: DISTRIBUCION
A4: Falla técnica (bugs críticos) | B4: 0.08 | C4: 0.08
A5: Retrasos en el cronograma | B5: 0.8 | E5: =B5 -> 0.8
A6: Falta de conocimientos técnicos | B6: 0.6 | D6: =B6 -> 0.6
A7: Problemas de compatibilidad | B7: 0.8 | E7: =B7 -> 0.8
A8: Pérdida de datos | B8: 0.3 | C8: =B8 -> 0.3
A9: Falta de presupuesto y recursos | B9: 0.2 | C9: =B9 -> 0.2
A10: Cambios en requisitos | B10: 0.7 | D10: =B10 -> 0.7
A11: Incopatibilidad entre modulos de la apliciacion | B11: 0.8 | E11: =B11 -> 0.8
A12: Documentacion incompleta | B12: 0.5 | D12: =B12 -> 0.5
A13: Falta de comunicacion entre miembros | B13: 0.88 | E13: =B13 -> 0.88
A14: IMPACTO | B14: PORCENTAJE | C14: =SUM(C4:C13)/COUNTA(C4:C13) -> 0.19333333 | D14: =SUM(D4:D13)/COUNTA(D4:D13) -> 0.6 | E14: =SUM(E4:E13)/COUNTA(E4:E13) -> 0.82
C15: Bajo | D15: Medio | E15: Alto
A18: DISTRIBUCIÒN | B18: RIESGO | C18: Clasificación Matriz del Riesgo (Bajo, Medio, Alto), escala 1 al 25 | D18: Clasificación Probabilidad(Bajo, Medio, Alto) Escala de 1 al 100% | E18: PORCENTAJE ASIGNADO DE LA PROBABILIDAD
A19: Bajo | B19: Verde: Riesgo bajo. | C19: 01 al 10 | D19: 01 al 19 | E19: 01 al 49 %
A20: Medio | B20: Amarillo: Riesgo moderado. | C20: 11 al 15 | D20: 20 al 50 | E20: 50 al 79%
A21: Alto | B21: Rojo: Riesgo alto o crítico. | C21: 16 al 25 | D21: 51 al 100 | E21: 80 al 100%
